[2025-03-24T00:20:08.089+0000] {taskinstance.py:1956} INFO - Dependencies all met for dep_context=non-requeueable deps ti=<TaskInstance: descargar_datos_api.obtener_datos_grupo_10 scheduled__2025-03-24T00:15:00+00:00 [queued]>
[2025-03-24T00:20:08.292+0000] {taskinstance.py:1956} INFO - Dependencies all met for dep_context=requeueable deps ti=<TaskInstance: descargar_datos_api.obtener_datos_grupo_10 scheduled__2025-03-24T00:15:00+00:00 [queued]>
[2025-03-24T00:20:08.294+0000] {taskinstance.py:2170} INFO - Starting attempt 1 of 1
[2025-03-24T00:20:08.718+0000] {taskinstance.py:2191} INFO - Executing <Task(PythonOperator): obtener_datos_grupo_10> on 2025-03-24 00:15:00+00:00
[2025-03-24T00:20:08.823+0000] {standard_task_runner.py:60} INFO - Started process 300 to run task
[2025-03-24T00:20:08.904+0000] {standard_task_runner.py:87} INFO - Running: ['***', 'tasks', 'run', 'descargar_datos_api', 'obtener_datos_grupo_10', 'scheduled__2025-03-24T00:15:00+00:00', '--job-id', '33', '--raw', '--subdir', 'DAGS_FOLDER/descargar_datos_api.py', '--cfg-path', '/tmp/tmpvsodpgaq']
[2025-03-24T00:20:08.967+0000] {standard_task_runner.py:88} INFO - Job 33: Subtask obtener_datos_grupo_10
[2025-03-24T00:20:09.951+0000] {task_command.py:423} INFO - Running <TaskInstance: descargar_datos_api.obtener_datos_grupo_10 scheduled__2025-03-24T00:15:00+00:00 [running]> on host 823281a76116
[2025-03-24T00:20:11.250+0000] {taskinstance.py:2480} INFO - Exporting env vars: AIRFLOW_CTX_DAG_OWNER='***' AIRFLOW_CTX_DAG_ID='descargar_datos_api' AIRFLOW_CTX_TASK_ID='obtener_datos_grupo_10' AIRFLOW_CTX_EXECUTION_DATE='2025-03-24T00:15:00+00:00' AIRFLOW_CTX_TRY_NUMBER='1' AIRFLOW_CTX_DAG_RUN_ID='scheduled__2025-03-24T00:15:00+00:00'
[2025-03-24T00:20:13.772+0000] {descargar_datos_api.py:33} ERROR - [Grupo 10] Error al obtener datos: 500 Server Error: Internal Server Error for url: http://10.43.101.187/data?group_number=10
[2025-03-24T00:20:13.779+0000] {taskinstance.py:2698} ERROR - Task failed with exception
Traceback (most recent call last):
  File "/home/airflow/.local/lib/python3.8/site-packages/airflow/models/taskinstance.py", line 433, in _execute_task
    result = execute_callable(context=context, **execute_callable_kwargs)
  File "/home/airflow/.local/lib/python3.8/site-packages/airflow/operators/python.py", line 199, in execute
    return_value = self.execute_callable()
  File "/home/airflow/.local/lib/python3.8/site-packages/airflow/operators/python.py", line 216, in execute_callable
    return self.python_callable(*self.op_args, **self.op_kwargs)
  File "/opt/airflow/dags/descargar_datos_api.py", line 16, in obtener_datos
    response.raise_for_status()  # Lanza error si hay problema HTTP
  File "/home/airflow/.local/lib/python3.8/site-packages/requests/models.py", line 1021, in raise_for_status
    raise HTTPError(http_error_msg, response=self)
requests.exceptions.HTTPError: 500 Server Error: Internal Server Error for url: http://10.43.101.187/data?group_number=10
[2025-03-24T00:20:13.868+0000] {taskinstance.py:1138} INFO - Marking task as FAILED. dag_id=descargar_datos_api, task_id=obtener_datos_grupo_10, execution_date=20250324T001500, start_date=20250324T002008, end_date=20250324T002013
[2025-03-24T00:20:15.953+0000] {standard_task_runner.py:107} ERROR - Failed to execute job 33 for task obtener_datos_grupo_10 (500 Server Error: Internal Server Error for url: http://10.43.101.187/data?group_number=10; 300)
[2025-03-24T00:20:16.019+0000] {local_task_job_runner.py:234} INFO - Task exited with return code 1
[2025-03-24T00:20:16.401+0000] {taskinstance.py:3280} INFO - 0 downstream tasks scheduled from follow-on schedule check
