[2025-03-24T00:17:02.698+0000] {taskinstance.py:1956} INFO - Dependencies all met for dep_context=non-requeueable deps ti=<TaskInstance: descargar_datos_api.obtener_datos_grupo_10 scheduled__2025-03-24T00:10:00+00:00 [queued]>
[2025-03-24T00:17:03.019+0000] {taskinstance.py:1956} INFO - Dependencies all met for dep_context=requeueable deps ti=<TaskInstance: descargar_datos_api.obtener_datos_grupo_10 scheduled__2025-03-24T00:10:00+00:00 [queued]>
[2025-03-24T00:17:03.020+0000] {taskinstance.py:2170} INFO - Starting attempt 1 of 1
[2025-03-24T00:17:03.469+0000] {taskinstance.py:2191} INFO - Executing <Task(PythonOperator): obtener_datos_grupo_10> on 2025-03-24 00:10:00+00:00
[2025-03-24T00:17:03.483+0000] {standard_task_runner.py:60} INFO - Started process 217 to run task
[2025-03-24T00:17:03.515+0000] {standard_task_runner.py:87} INFO - Running: ['***', 'tasks', 'run', 'descargar_datos_api', 'obtener_datos_grupo_10', 'scheduled__2025-03-24T00:10:00+00:00', '--job-id', '13', '--raw', '--subdir', 'DAGS_FOLDER/descargar_datos_api.py', '--cfg-path', '/tmp/tmpfgcjzkon']
[2025-03-24T00:17:03.542+0000] {standard_task_runner.py:88} INFO - Job 13: Subtask obtener_datos_grupo_10
[2025-03-24T00:17:04.151+0000] {task_command.py:423} INFO - Running <TaskInstance: descargar_datos_api.obtener_datos_grupo_10 scheduled__2025-03-24T00:10:00+00:00 [running]> on host 823281a76116
[2025-03-24T00:17:05.374+0000] {taskinstance.py:2480} INFO - Exporting env vars: AIRFLOW_CTX_DAG_OWNER='***' AIRFLOW_CTX_DAG_ID='descargar_datos_api' AIRFLOW_CTX_TASK_ID='obtener_datos_grupo_10' AIRFLOW_CTX_EXECUTION_DATE='2025-03-24T00:10:00+00:00' AIRFLOW_CTX_TRY_NUMBER='1' AIRFLOW_CTX_DAG_RUN_ID='scheduled__2025-03-24T00:10:00+00:00'
[2025-03-24T00:17:11.263+0000] {descargar_datos_api.py:33} ERROR - [Grupo 10] Error al obtener datos: 500 Server Error: Internal Server Error for url: http://10.43.101.187/data?group_number=10
[2025-03-24T00:17:11.273+0000] {taskinstance.py:2698} ERROR - Task failed with exception
Traceback (most recent call last):
  File "/home/airflow/.local/lib/python3.8/site-packages/airflow/models/taskinstance.py", line 433, in _execute_task
    result = execute_callable(context=context, **execute_callable_kwargs)
  File "/home/airflow/.local/lib/python3.8/site-packages/airflow/operators/python.py", line 199, in execute
    return_value = self.execute_callable()
  File "/home/airflow/.local/lib/python3.8/site-packages/airflow/operators/python.py", line 216, in execute_callable
    return self.python_callable(*self.op_args, **self.op_kwargs)
  File "/opt/airflow/dags/descargar_datos_api.py", line 16, in obtener_datos
    response.raise_for_status()  # Lanza error si hay problema HTTP
  File "/home/airflow/.local/lib/python3.8/site-packages/requests/models.py", line 1021, in raise_for_status
    raise HTTPError(http_error_msg, response=self)
requests.exceptions.HTTPError: 500 Server Error: Internal Server Error for url: http://10.43.101.187/data?group_number=10
[2025-03-24T00:17:11.374+0000] {taskinstance.py:1138} INFO - Marking task as FAILED. dag_id=descargar_datos_api, task_id=obtener_datos_grupo_10, execution_date=20250324T001000, start_date=20250324T001702, end_date=20250324T001711
[2025-03-24T00:17:14.069+0000] {standard_task_runner.py:107} ERROR - Failed to execute job 13 for task obtener_datos_grupo_10 (500 Server Error: Internal Server Error for url: http://10.43.101.187/data?group_number=10; 217)
[2025-03-24T00:17:14.267+0000] {local_task_job_runner.py:234} INFO - Task exited with return code 1
[2025-03-24T00:17:14.604+0000] {taskinstance.py:3280} INFO - 0 downstream tasks scheduled from follow-on schedule check
