[2025-03-24T00:17:16.178+0000] {taskinstance.py:1956} INFO - Dependencies all met for dep_context=non-requeueable deps ti=<TaskInstance: descargar_datos_api.obtener_datos_grupo_9 manual__2025-03-24T00:16:53.960584+00:00 [queued]>
[2025-03-24T00:17:16.205+0000] {taskinstance.py:1956} INFO - Dependencies all met for dep_context=requeueable deps ti=<TaskInstance: descargar_datos_api.obtener_datos_grupo_9 manual__2025-03-24T00:16:53.960584+00:00 [queued]>
[2025-03-24T00:17:16.206+0000] {taskinstance.py:2170} INFO - Starting attempt 1 of 1
[2025-03-24T00:17:16.236+0000] {taskinstance.py:2191} INFO - Executing <Task(PythonOperator): obtener_datos_grupo_9> on 2025-03-24 00:16:53.960584+00:00
[2025-03-24T00:17:16.254+0000] {standard_task_runner.py:60} INFO - Started process 240 to run task
[2025-03-24T00:17:16.267+0000] {standard_task_runner.py:87} INFO - Running: ['***', 'tasks', 'run', 'descargar_datos_api', 'obtener_datos_grupo_9', 'manual__2025-03-24T00:16:53.960584+00:00', '--job-id', '23', '--raw', '--subdir', 'DAGS_FOLDER/descargar_datos_api.py', '--cfg-path', '/tmp/tmpgscbrjxp']
[2025-03-24T00:17:16.272+0000] {standard_task_runner.py:88} INFO - Job 23: Subtask obtener_datos_grupo_9
[2025-03-24T00:17:16.431+0000] {task_command.py:423} INFO - Running <TaskInstance: descargar_datos_api.obtener_datos_grupo_9 manual__2025-03-24T00:16:53.960584+00:00 [running]> on host 823281a76116
[2025-03-24T00:17:16.627+0000] {taskinstance.py:2480} INFO - Exporting env vars: AIRFLOW_CTX_DAG_OWNER='***' AIRFLOW_CTX_DAG_ID='descargar_datos_api' AIRFLOW_CTX_TASK_ID='obtener_datos_grupo_9' AIRFLOW_CTX_EXECUTION_DATE='2025-03-24T00:16:53.960584+00:00' AIRFLOW_CTX_TRY_NUMBER='1' AIRFLOW_CTX_DAG_RUN_ID='manual__2025-03-24T00:16:53.960584+00:00'
[2025-03-24T00:17:17.661+0000] {descargar_datos_api.py:33} ERROR - [Grupo 9] Error al obtener datos: [Errno 13] Permission denied: '/opt/***/datasets/group_9'
[2025-03-24T00:17:17.662+0000] {taskinstance.py:2698} ERROR - Task failed with exception
Traceback (most recent call last):
  File "/home/airflow/.local/lib/python3.8/site-packages/airflow/models/taskinstance.py", line 433, in _execute_task
    result = execute_callable(context=context, **execute_callable_kwargs)
  File "/home/airflow/.local/lib/python3.8/site-packages/airflow/operators/python.py", line 199, in execute
    return_value = self.execute_callable()
  File "/home/airflow/.local/lib/python3.8/site-packages/airflow/operators/python.py", line 216, in execute_callable
    return self.python_callable(*self.op_args, **self.op_kwargs)
  File "/opt/airflow/dags/descargar_datos_api.py", line 24, in obtener_datos
    os.makedirs(group_dir, exist_ok=True)
  File "/usr/local/lib/python3.8/os.py", line 223, in makedirs
    mkdir(name, mode)
PermissionError: [Errno 13] Permission denied: '/opt/airflow/datasets/group_9'
[2025-03-24T00:17:17.677+0000] {taskinstance.py:1138} INFO - Marking task as FAILED. dag_id=descargar_datos_api, task_id=obtener_datos_grupo_9, execution_date=20250324T001653, start_date=20250324T001716, end_date=20250324T001717
[2025-03-24T00:17:17.699+0000] {standard_task_runner.py:107} ERROR - Failed to execute job 23 for task obtener_datos_grupo_9 ([Errno 13] Permission denied: '/opt/airflow/datasets/group_9'; 240)
[2025-03-24T00:17:17.776+0000] {local_task_job_runner.py:234} INFO - Task exited with return code 1
[2025-03-24T00:17:17.816+0000] {taskinstance.py:3280} INFO - 0 downstream tasks scheduled from follow-on schedule check
