[2025-03-24T00:17:01.513+0000] {taskinstance.py:1956} INFO - Dependencies all met for dep_context=non-requeueable deps ti=<TaskInstance: descargar_datos_api.obtener_datos_grupo_7 scheduled__2025-03-24T00:10:00+00:00 [queued]>
[2025-03-24T00:17:01.788+0000] {taskinstance.py:1956} INFO - Dependencies all met for dep_context=requeueable deps ti=<TaskInstance: descargar_datos_api.obtener_datos_grupo_7 scheduled__2025-03-24T00:10:00+00:00 [queued]>
[2025-03-24T00:17:01.802+0000] {taskinstance.py:2170} INFO - Starting attempt 1 of 1
[2025-03-24T00:17:02.054+0000] {taskinstance.py:2191} INFO - Executing <Task(PythonOperator): obtener_datos_grupo_7> on 2025-03-24 00:10:00+00:00
[2025-03-24T00:17:02.446+0000] {standard_task_runner.py:87} INFO - Running: ['***', 'tasks', 'run', 'descargar_datos_api', 'obtener_datos_grupo_7', 'scheduled__2025-03-24T00:10:00+00:00', '--job-id', '10', '--raw', '--subdir', 'DAGS_FOLDER/descargar_datos_api.py', '--cfg-path', '/tmp/tmpo9x2418i']
[2025-03-24T00:17:02.451+0000] {standard_task_runner.py:88} INFO - Job 10: Subtask obtener_datos_grupo_7
[2025-03-24T00:17:02.380+0000] {standard_task_runner.py:60} INFO - Started process 215 to run task
[2025-03-24T00:17:03.904+0000] {task_command.py:423} INFO - Running <TaskInstance: descargar_datos_api.obtener_datos_grupo_7 scheduled__2025-03-24T00:10:00+00:00 [running]> on host 823281a76116
[2025-03-24T00:17:05.301+0000] {taskinstance.py:2480} INFO - Exporting env vars: AIRFLOW_CTX_DAG_OWNER='***' AIRFLOW_CTX_DAG_ID='descargar_datos_api' AIRFLOW_CTX_TASK_ID='obtener_datos_grupo_7' AIRFLOW_CTX_EXECUTION_DATE='2025-03-24T00:10:00+00:00' AIRFLOW_CTX_TRY_NUMBER='1' AIRFLOW_CTX_DAG_RUN_ID='scheduled__2025-03-24T00:10:00+00:00'
[2025-03-24T00:17:12.705+0000] {descargar_datos_api.py:33} ERROR - [Grupo 7] Error al obtener datos: [Errno 13] Permission denied: '/opt/***/datasets/group_7'
[2025-03-24T00:17:12.713+0000] {taskinstance.py:2698} ERROR - Task failed with exception
Traceback (most recent call last):
  File "/home/airflow/.local/lib/python3.8/site-packages/airflow/models/taskinstance.py", line 433, in _execute_task
    result = execute_callable(context=context, **execute_callable_kwargs)
  File "/home/airflow/.local/lib/python3.8/site-packages/airflow/operators/python.py", line 199, in execute
    return_value = self.execute_callable()
  File "/home/airflow/.local/lib/python3.8/site-packages/airflow/operators/python.py", line 216, in execute_callable
    return self.python_callable(*self.op_args, **self.op_kwargs)
  File "/opt/airflow/dags/descargar_datos_api.py", line 24, in obtener_datos
    os.makedirs(group_dir, exist_ok=True)
  File "/usr/local/lib/python3.8/os.py", line 223, in makedirs
    mkdir(name, mode)
PermissionError: [Errno 13] Permission denied: '/opt/airflow/datasets/group_7'
[2025-03-24T00:17:12.855+0000] {taskinstance.py:1138} INFO - Marking task as FAILED. dag_id=descargar_datos_api, task_id=obtener_datos_grupo_7, execution_date=20250324T001000, start_date=20250324T001701, end_date=20250324T001712
[2025-03-24T00:17:14.220+0000] {standard_task_runner.py:107} ERROR - Failed to execute job 10 for task obtener_datos_grupo_7 ([Errno 13] Permission denied: '/opt/airflow/datasets/group_7'; 215)
[2025-03-24T00:17:14.384+0000] {local_task_job_runner.py:234} INFO - Task exited with return code 1
[2025-03-24T00:17:14.786+0000] {taskinstance.py:3280} INFO - 0 downstream tasks scheduled from follow-on schedule check
