[2025-03-24T00:17:01.298+0000] {taskinstance.py:1956} INFO - Dependencies all met for dep_context=non-requeueable deps ti=<TaskInstance: descargar_datos_api.obtener_datos_grupo_2 scheduled__2025-03-24T00:10:00+00:00 [queued]>
[2025-03-24T00:17:01.408+0000] {taskinstance.py:1956} INFO - Dependencies all met for dep_context=requeueable deps ti=<TaskInstance: descargar_datos_api.obtener_datos_grupo_2 scheduled__2025-03-24T00:10:00+00:00 [queued]>
[2025-03-24T00:17:01.437+0000] {taskinstance.py:2170} INFO - Starting attempt 1 of 1
[2025-03-24T00:17:01.648+0000] {taskinstance.py:2191} INFO - Executing <Task(PythonOperator): obtener_datos_grupo_2> on 2025-03-24 00:10:00+00:00
[2025-03-24T00:17:01.818+0000] {standard_task_runner.py:60} INFO - Started process 212 to run task
[2025-03-24T00:17:01.925+0000] {standard_task_runner.py:87} INFO - Running: ['***', 'tasks', 'run', 'descargar_datos_api', 'obtener_datos_grupo_2', 'scheduled__2025-03-24T00:10:00+00:00', '--job-id', '9', '--raw', '--subdir', 'DAGS_FOLDER/descargar_datos_api.py', '--cfg-path', '/tmp/tmp3k48hba8']
[2025-03-24T00:17:01.968+0000] {standard_task_runner.py:88} INFO - Job 9: Subtask obtener_datos_grupo_2
[2025-03-24T00:17:03.595+0000] {task_command.py:423} INFO - Running <TaskInstance: descargar_datos_api.obtener_datos_grupo_2 scheduled__2025-03-24T00:10:00+00:00 [running]> on host 823281a76116
[2025-03-24T00:17:05.142+0000] {taskinstance.py:2480} INFO - Exporting env vars: AIRFLOW_CTX_DAG_OWNER='***' AIRFLOW_CTX_DAG_ID='descargar_datos_api' AIRFLOW_CTX_TASK_ID='obtener_datos_grupo_2' AIRFLOW_CTX_EXECUTION_DATE='2025-03-24T00:10:00+00:00' AIRFLOW_CTX_TRY_NUMBER='1' AIRFLOW_CTX_DAG_RUN_ID='scheduled__2025-03-24T00:10:00+00:00'
[2025-03-24T00:17:14.611+0000] {descargar_datos_api.py:33} ERROR - [Grupo 2] Error al obtener datos: [Errno 13] Permission denied: '/opt/***/datasets/group_2'
[2025-03-24T00:17:14.621+0000] {taskinstance.py:2698} ERROR - Task failed with exception
Traceback (most recent call last):
  File "/home/airflow/.local/lib/python3.8/site-packages/airflow/models/taskinstance.py", line 433, in _execute_task
    result = execute_callable(context=context, **execute_callable_kwargs)
  File "/home/airflow/.local/lib/python3.8/site-packages/airflow/operators/python.py", line 199, in execute
    return_value = self.execute_callable()
  File "/home/airflow/.local/lib/python3.8/site-packages/airflow/operators/python.py", line 216, in execute_callable
    return self.python_callable(*self.op_args, **self.op_kwargs)
  File "/opt/airflow/dags/descargar_datos_api.py", line 24, in obtener_datos
    os.makedirs(group_dir, exist_ok=True)
  File "/usr/local/lib/python3.8/os.py", line 223, in makedirs
    mkdir(name, mode)
PermissionError: [Errno 13] Permission denied: '/opt/airflow/datasets/group_2'
[2025-03-24T00:17:14.654+0000] {taskinstance.py:1138} INFO - Marking task as FAILED. dag_id=descargar_datos_api, task_id=obtener_datos_grupo_2, execution_date=20250324T001000, start_date=20250324T001701, end_date=20250324T001714
[2025-03-24T00:17:14.829+0000] {standard_task_runner.py:107} ERROR - Failed to execute job 9 for task obtener_datos_grupo_2 ([Errno 13] Permission denied: '/opt/airflow/datasets/group_2'; 212)
[2025-03-24T00:17:14.938+0000] {local_task_job_runner.py:234} INFO - Task exited with return code 1
[2025-03-24T00:17:15.051+0000] {taskinstance.py:3280} INFO - 0 downstream tasks scheduled from follow-on schedule check
